<sdf version='1.7'>
  <world name='default'>
    <light name='sun' type='directional'>
      <cast_shadows>0</cast_shadows>
      <pose>0 0 10 0 -0 0</pose>
      <diffuse>0.8 0.8 0.8 1</diffuse>
      <specular>0.2 0.2 0.2 1</specular>
      <attenuation>
        <range>1000</range>
        <constant>0.9</constant>
        <linear>0.01</linear>
        <quadratic>0.001</quadratic>
      </attenuation>
      <direction>-0.5 0.1 -0.9</direction>
      <spot>
        <inner_angle>0</inner_angle>
        <outer_angle>0</outer_angle>
        <falloff>0</falloff>
      </spot>
    </light>
    <model name='pedestrian2'>
      <pose>1 -5 0.5 0 -0 0</pose>
      <link name='link'>
        <collision name='collision'>
          <geometry>
            <box>
              <size>0.2 0.75 3</size>
            </box>
          </geometry>
          <max_contacts>10</max_contacts>
          <surface>
            <contact>
              <ode/>
            </contact>
            <bounce/>
            <friction>
              <torsional>
                <ode/>
              </torsional>
              <ode/>
            </friction>
          </surface>
        </collision>
        <visual name='visual'>
          <geometry>
            <box>
              <size>0.2 0.8 3</size>
            </box>
          </geometry>
        </visual>
        <self_collide>0</self_collide>
        <inertial>
          <pose>0 0 0 0 -0 0</pose>
          <inertia>
            <ixx>1</ixx>
            <ixy>0</ixy>
            <ixz>0</ixz>
            <iyy>1</iyy>
            <iyz>0</iyz>
            <izz>1</izz>
          </inertia>
          <mass>1</mass>
        </inertial>
        <enable_wind>0</enable_wind>
        <kinematic>0</kinematic>
      </link>
      <plugin name='push_animate_2' filename='libanimated_box.so'/>
    </model>
    <model name='ground_plane'>
      <static>1</static>
      <link name='link'>
        <collision name='collision'>
          <geometry>
            <plane>
              <normal>0 0 1</normal>
              <size>100 100</size>
            </plane>
          </geometry>
          <surface>
            <contact>
              <collide_bitmask>65535</collide_bitmask>
              <ode/>
            </contact>
            <friction>
              <ode>
                <mu>100</mu>
                <mu2>50</mu2>
              </ode>
              <torsional>
                <ode/>
              </torsional>
            </friction>
            <bounce/>
          </surface>
          <max_contacts>10</max_contacts>
        </collision>
        <visual name='visual'>
          <cast_shadows>0</cast_shadows>
          <geometry>
            <plane>
              <normal>0 0 1</normal>
              <size>100 100</size>
            </plane>
          </geometry>
          <material>
            <script>
              <uri>file://media/materials/scripts/gazebo.material</uri>
              <name>Gazebo/Grey</name>
            </script>
          </material>
        </visual>
        <self_collide>0</self_collide>
        <enable_wind>0</enable_wind>
        <kinematic>0</kinematic>
      </link>
    </model>
    <gravity>0 0 -9.8</gravity>
    <magnetic_field>6e-06 2.3e-05 -4.2e-05</magnetic_field>
    <atmosphere type='adiabatic'/>
    <physics type='ode'>
      <max_step_size>0.001</max_step_size>
      <real_time_factor>1</real_time_factor>
      <real_time_update_rate>1000</real_time_update_rate>
    </physics>
    <scene>
      <ambient>0.4 0.4 0.4 1</ambient>
      <background>0.7 0.7 0.7 1</background>
      <shadows>0</shadows>
    </scene>
    <wind/>
    <spherical_coordinates>
      <surface_model>EARTH_WGS84</surface_model>
      <latitude_deg>0</latitude_deg>
      <longitude_deg>0</longitude_deg>
      <elevation>0</elevation>
      <heading_deg>0</heading_deg>
    </spherical_coordinates>
    <state world_name='default'>
      <sim_time>1010 727000000</sim_time>
      <real_time>220 364743981</real_time>
      <wall_time>1669359360 725702046</wall_time>
      <iterations>208095</iterations>
      <model name='/'>
        <pose>14.9413 0.578004 -8e-06 -3.6e-05 -0.00014 3.10304</pose>
        <scale>1 1 1</scale>
        <link name='base_footprint'>
          <pose>14.9413 0.578004 -8e-06 -3.6e-05 -0.00014 3.10304</pose>
          <velocity>-0.000804 0.000815 -0.000909 0.006098 0.00223 -0.006811</velocity>
          <acceleration>4.1e-05 -1e-06 -1.3e-05 0.008096 0.000167 0.000587</acceleration>
          <wrench>0.000163 -4e-06 -5.3e-05 0 -0 0</wrench>
        </link>
        <link name='left_wheel_link'>
          <pose>14.9759 0.436557 0.04686 3.14041 1.03743 -0.039601</pose>
          <velocity>-0.001991 0.000166 -0.001461 -0.001179 0.009964 -0.004971</velocity>
          <acceleration>4.1e-05 1e-06 -8e-06 -0.757697 0.014268 0.011877</acceleration>
          <wrench>6e-06 0 -1e-06 0 -0 0</wrench>
        </link>
        <link name='rear_caster_base'>
          <pose>15.1412 0.570293 0.066522 -0.000156 9.2e-05 -1.733</pose>
          <velocity>-0.000625 -0.000923 -0.001664 0.003327 -0.000125 -0.006298</velocity>
          <acceleration>2.9e-05 4e-06 -8.1e-05 7.4e-05 0.000875 0.000651</acceleration>
          <wrench>2e-06 0 -5e-06 0 -0 0</wrench>
        </link>
        <link name='rear_caster_link'>
          <pose>15.1454 0.596206 0.024151 -0.0008 -1.21434 -1.73224</pose>
          <velocity>-0.000392 -0.000603 -0.001985 -0.191846 0.020134 -0.002439</velocity>
          <acceleration>1e-05 2.4e-05 -0.000116 0.388734 -0.122588 0.104152</acceleration>
          <wrench>0 1e-06 -4e-06 0 -0 0</wrench>
        </link>
        <link name='right_wheel_link'>
          <pose>14.9867 0.716366 0.046871 -3.14069 0.606422 -0.037999</pose>
          <velocity>0.000276 9.3e-05 -0.000107 -0.001795 0.007214 -0.005097</velocity>
          <acceleration>3.6e-05 -3e-06 3.1e-05 -0.475125 0.00897 -0.009174</acceleration>
          <wrench>5e-06 -0 4e-06 0 -0 0</wrench>
        </link>
      </model>
      <model name='ground_plane'>
        <pose>0 0 0 0 -0 0</pose>
        <scale>1 1 1</scale>
        <link name='link'>
          <pose>0 0 0 0 -0 0</pose>
          <velocity>0 0 0 0 -0 0</velocity>
          <acceleration>0 0 0 0 -0 0</acceleration>
          <wrench>0 0 0 0 -0 0</wrench>
        </link>
      </model>
      <model name='pedestrian2'>
        <pose>7.50894 0.00077 1.50436 0.000421 -0.025511 -0.002092</pose>
        <scale>1 1 1</scale>
        <link name='link'>
          <pose>7.50894 0.00077 1.50436 0.000421 -0.025511 -0.002092</pose>
          <velocity>-0.000445 7.6e-05 0.010053 -4.9e-05 -0.000301 -4.8e-05</velocity>
          <acceleration>-0 0 0 0 -0 0</acceleration>
          <wrench>-0 0 0 0 -0 0</wrench>
        </link>
      </model>
      <light name='sun'>
        <pose>0 0 10 0 -0 0</pose>
      </light>
    </state>
    <gui fullscreen='0'>
      <camera name='user_camera'>
        <pose>32.626 13.578 6.91251 0 0.444049 -2.36859</pose>
        <view_controller>orbit</view_controller>
        <projection_type>perspective</projection_type>
      </camera>
    </gui>
    <model name='/'>
      <link name='base_footprint'>
        <inertial>
          <pose>-0.107998 0 0.066091 0 -0 0</pose>
          <mass>3.97804</mass>
          <inertia>
            <ixx>0.0218636</ixx>
            <ixy>0</ixy>
            <ixz>0.0100199</ixz>
            <iyy>0.0785781</iyy>
            <iyz>0</iyz>
            <izz>0.0919777</izz>
          </inertia>
        </inertial>
        <collision name='base_footprint_fixed_joint_lump__base_link_collision'>
          <pose>-0.125 0 0.08188 0 -0 0</pose>
          <geometry>
            <box>
              <size>0.25 0.25 0.02</size>
            </box>
          </geometry>
          <max_contacts>10</max_contacts>
          <surface>
            <contact>
              <ode/>
            </contact>
            <bounce/>
            <friction>
              <torsional>
                <ode/>
              </torsional>
              <ode/>
            </friction>
          </surface>
        </collision>
        <collision name='base_footprint_fixed_joint_lump__camera_left_link_collision_1'>
          <pose>0.12 -0.2 0.12688 0 0 -1.75</pose>
          <geometry>
            <box>
              <size>0.05 0.05 0.05</size>
            </box>
          </geometry>
          <surface>
            <contact>
              <ode/>
            </contact>
            <friction>
              <ode/>
              <torsional>
                <ode/>
              </torsional>
            </friction>
            <bounce/>
          </surface>
          <max_contacts>10</max_contacts>
        </collision>
        <collision name='base_footprint_fixed_joint_lump__camera_right_link_collision_2'>
          <pose>0.12 0.2 0.12688 0 -0 1.75</pose>
          <geometry>
            <box>
              <size>0.05 0.05 0.05</size>
            </box>
          </geometry>
          <surface>
            <contact>
              <ode/>
            </contact>
            <friction>
              <ode/>
              <torsional>
                <ode/>
              </torsional>
            </friction>
            <bounce/>
          </surface>
          <max_contacts>10</max_contacts>
        </collision>
        <collision name='base_footprint_fixed_joint_lump__imu_link_collision_3'>
          <pose>0 0 0.14188 0 -0 0</pose>
          <geometry>
            <box>
              <size>0.01 0.01 0.015</size>
            </box>
          </geometry>
          <surface>
            <contact>
              <ode/>
            </contact>
            <friction>
              <ode/>
              <torsional>
                <ode/>
              </torsional>
            </friction>
            <bounce/>
          </surface>
          <max_contacts>10</max_contacts>
        </collision>
        <collision name='base_footprint_fixed_joint_lump__stereo_camera_link_collision_4'>
          <pose>0.1 0 0.12688 0 -0 0</pose>
          <geometry>
            <box>
              <size>0.05 0.05 0.05</size>
            </box>
          </geometry>
          <surface>
            <contact>
              <ode/>
            </contact>
            <friction>
              <ode/>
              <torsional>
                <ode/>
              </torsional>
            </friction>
            <bounce/>
          </surface>
          <max_contacts>10</max_contacts>
        </collision>
        <visual name='base_footprint_fixed_joint_lump__base_link_visual'>
          <pose>0 0 0.09188 0 -0 0</pose>
          <geometry>
            <mesh>
              <scale>1 1 1</scale>
              <uri>/home/ikemura/ROS_workspaces/HKUST_RGD_SIM/src/onebot_description/meshes/base_link.dae</uri>
            </mesh>
          </geometry>
        </visual>
        <visual name='base_footprint_fixed_joint_lump__camera_left_link_visual_1'>
          <pose>0.12 -0.2 0.12688 0 0 -1.75</pose>
          <geometry>
            <box>
              <size>0.05 0.05 0.05</size>
            </box>
          </geometry>
        </visual>
        <visual name='base_footprint_fixed_joint_lump__camera_right_link_visual_2'>
          <pose>0.12 0.2 0.12688 0 -0 1.75</pose>
          <geometry>
            <box>
              <size>0.05 0.05 0.05</size>
            </box>
          </geometry>
        </visual>
        <visual name='base_footprint_fixed_joint_lump__imu_link_visual_3'>
          <pose>0 0 0.14188 0 -0 0</pose>
          <geometry>
            <box>
              <size>0.01 0.01 0.015</size>
            </box>
          </geometry>
        </visual>
        <visual name='base_footprint_fixed_joint_lump__stereo_camera_link_visual_4'>
          <pose>0.1 0 0.12688 0 -0 0</pose>
          <geometry>
            <box>
              <size>0.05 0.05 0.05</size>
            </box>
          </geometry>
        </visual>
        <sensor name='camera1' type='camera'>
          <update_rate>30</update_rate>
          <camera name='head'>
            <horizontal_fov>1.39626</horizontal_fov>
            <image>
              <width>800</width>
              <height>800</height>
              <format>R8G8B8</format>
            </image>
            <clip>
              <near>0.02</near>
              <far>300</far>
            </clip>
            <noise>
              <type>gaussian</type>
              <mean>0</mean>
              <stddev>0.007</stddev>
            </noise>
          </camera>
          <plugin name='camera_controller' filename='libgazebo_ros_camera.so'>
            <alwaysOn>1</alwaysOn>
            <updateRate>0.0</updateRate>
            <cameraName>onebot/left</cameraName>
            <imageTopicName>image_raw</imageTopicName>
            <cameraInfoTopicName>camera_info</cameraInfoTopicName>
            <frameName>camera_left_link</frameName>
            <hackBaseline>0.07</hackBaseline>
            <distortionK1>0.0</distortionK1>
            <distortionK2>0.0</distortionK2>
            <distortionK3>0.0</distortionK3>
            <distortionT1>0.0</distortionT1>
            <distortionT2>0.0</distortionT2>
            <robotNamespace>/</robotNamespace>
          </plugin>
          <pose>0.12 -0.2 0.12688 0 0 -1.75</pose>
        </sensor>
        <sensor name='camera1' type='camera'>
          <update_rate>30</update_rate>
          <camera name='head'>
            <horizontal_fov>1.39626</horizontal_fov>
            <image>
              <width>800</width>
              <height>800</height>
              <format>R8G8B8</format>
            </image>
            <clip>
              <near>0.02</near>
              <far>300</far>
            </clip>
            <noise>
              <type>gaussian</type>
              <mean>0</mean>
              <stddev>0.007</stddev>
            </noise>
          </camera>
          <plugin name='camera_controller' filename='libgazebo_ros_camera.so'>
            <alwaysOn>1</alwaysOn>
            <updateRate>0.0</updateRate>
            <cameraName>onebot/right</cameraName>
            <imageTopicName>image_raw</imageTopicName>
            <cameraInfoTopicName>camera_info</cameraInfoTopicName>
            <frameName>camera_right_link</frameName>
            <hackBaseline>0.07</hackBaseline>
            <distortionK1>0.0</distortionK1>
            <distortionK2>0.0</distortionK2>
            <distortionK3>0.0</distortionK3>
            <distortionT1>0.0</distortionT1>
            <distortionT2>0.0</distortionT2>
            <robotNamespace>/</robotNamespace>
          </plugin>
          <pose>0.12 0.2 0.12688 0 -0 1.75</pose>
        </sensor>
        <gravity>1</gravity>
        <sensor name='imu_sensor' type='imu'>
          <always_on>1</always_on>
          <update_rate>100</update_rate>
          <visualize>1</visualize>
          <topic>__default_topic__</topic>
          <plugin name='imu_plugin' filename='libgazebo_ros_imu_sensor.so'>
            <topicName>imu</topicName>
            <bodyName>imu_link</bodyName>
            <updateRateHZ>100.0</updateRateHZ>
            <gaussianNoise>0.0</gaussianNoise>
            <xyzOffset>0 0 0</xyzOffset>
            <rpyOffset>0 0 0</rpyOffset>
            <frameName>imu_link</frameName>
            <initialOrientationAsReference>0</initialOrientationAsReference>
            <robotNamespace>/</robotNamespace>
          </plugin>
          <pose>0 0 0.14188 0 -0 0</pose>
          <imu/>
        </sensor>
        <sensor name='stereo_camera_link' type='depth'>
          <update_rate>20</update_rate>
          <camera>
            <horizontal_fov>1.0472</horizontal_fov>
            <image>
              <width>640</width>
              <height>480</height>
              <format>R8G8B8</format>
            </image>
            <clip>
              <near>0.05</near>
              <far>3</far>
            </clip>
          </camera>
          <plugin name='stereo_camera_controller' filename='libgazebo_ros_openni_kinect.so'>
            <baseline>0.2</baseline>
            <alwaysOn>1</alwaysOn>
            <updateRate>1.0</updateRate>
            <cameraName>stereo_camera_ir</cameraName>
            <imageTopicName>/stereo_camera/color/image_raw</imageTopicName>
            <cameraInfoTopicName>/stereo_camera/color/camera_info</cameraInfoTopicName>
            <depthImageTopicName>/stereo_camera/depth/image_raw</depthImageTopicName>
            <depthImageInfoTopicName>/stereo_camera/depth/camera_info</depthImageInfoTopicName>
            <pointCloudTopicName>/stereo_camera/depth/points</pointCloudTopicName>
            <frameName>stereo_camera_link</frameName>
            <pointCloudCutoff>0.5</pointCloudCutoff>
            <pointCloudCutoffMax>3.0</pointCloudCutoffMax>
            <distortionK1>0.00000001</distortionK1>
            <distortionK2>0.00000001</distortionK2>
            <distortionK3>0.00000001</distortionK3>
            <distortionT1>0.00000001</distortionT1>
            <distortionT2>0.00000001</distortionT2>
            <CxPrime>0</CxPrime>
            <Cx>0</Cx>
            <Cy>0</Cy>
            <focalLength>0</focalLength>
            <hackBaseline>0</hackBaseline>
            <robotNamespace>/</robotNamespace>
          </plugin>
          <pose>0.1 0 0.12688 0 -0 0</pose>
        </sensor>
        <self_collide>0</self_collide>
        <enable_wind>0</enable_wind>
        <kinematic>0</kinematic>
      </link>
      <joint name='left_wheel' type='revolute'>
        <pose relative_to='base_footprint'>-0.04 0.14 0.04688 0 -0 0</pose>
        <parent>base_footprint</parent>
        <child>left_wheel_link</child>
        <axis>
          <xyz>0 1 0</xyz>
          <limit>
            <lower>-1e+16</lower>
            <upper>1e+16</upper>
          </limit>
          <dynamics>
            <damping>0.5</damping>
            <friction>100</friction>
            <spring_reference>0</spring_reference>
            <spring_stiffness>0</spring_stiffness>
          </dynamics>
        </axis>
      </joint>
      <link name='left_wheel_link'>
        <pose relative_to='left_wheel'>0 0 0 0 -0 0</pose>
        <inertial>
          <pose>0 0 0 0 -0 0</pose>
          <mass>0.144</mass>
          <inertia>
            <ixx>8.92986e-05</ixx>
            <ixy>0</ixy>
            <ixz>0</ixz>
            <iyy>0.000168983</iyy>
            <iyz>0</iyz>
            <izz>8.92986e-05</izz>
          </inertia>
        </inertial>
        <collision name='left_wheel_link_collision'>
          <pose>0 0 0 1.57 -0 0</pose>
          <geometry>
            <cylinder>
              <length>0.02</length>
              <radius>0.04688</radius>
            </cylinder>
          </geometry>
          <surface>
            <contact>
              <ode>
                <kp>600000</kp>
                <kd>3</kd>
              </ode>
            </contact>
            <friction>
              <ode>
                <mu>1e+07</mu>
                <mu2>1e+07</mu2>
                <fdir1>1 0 0</fdir1>
              </ode>
              <torsional>
                <ode/>
              </torsional>
            </friction>
            <bounce/>
          </surface>
          <max_contacts>10</max_contacts>
        </collision>
        <visual name='left_wheel_link_visual'>
          <pose>0 0 0 0 -0 1.57</pose>
          <geometry>
            <mesh>
              <scale>1 1 1</scale>
              <uri>/home/ikemura/ROS_workspaces/HKUST_RGD_SIM/src/onebot_description/meshes/wheel.dae</uri>
            </mesh>
          </geometry>
        </visual>
        <velocity_decay>
          <linear>0.05</linear>
          <angular>0.05</angular>
        </velocity_decay>
        <self_collide>0</self_collide>
        <enable_wind>0</enable_wind>
        <kinematic>0</kinematic>
      </link>
      <joint name='rear_caster' type='revolute'>
        <pose relative_to='base_footprint'>-0.2 0 0.06655 0 -0 0</pose>
        <parent>base_footprint</parent>
        <child>rear_caster_base</child>
        <axis>
          <xyz>0 0 1</xyz>
          <limit>
            <lower>-1e+16</lower>
            <upper>1e+16</upper>
          </limit>
          <dynamics>
            <damping>0</damping>
            <friction>0.1</friction>
            <spring_reference>0</spring_reference>
            <spring_stiffness>0</spring_stiffness>
          </dynamics>
        </axis>
      </joint>
      <link name='rear_caster_base'>
        <pose relative_to='rear_caster'>0 0 0 0 -0 0</pose>
        <inertial>
          <pose>-0.01204 0 -0.01454 0 -0 0</pose>
          <mass>0.06597</mass>
          <inertia>
            <ixx>3.9912e-05</ixx>
            <ixy>0</ixy>
            <ixz>1.7794e-05</ixz>
            <iyy>5.0728e-05</iyy>
            <iyz>0</iyz>
            <izz>3.5261e-05</izz>
          </inertia>
        </inertial>
        <collision name='rear_caster_base_collision'>
          <pose>0 0 -0.0075 0 -0 0</pose>
          <geometry>
            <cylinder>
              <length>0.015</length>
              <radius>0.015</radius>
            </cylinder>
          </geometry>
          <surface>
            <contact>
              <ode>
                <kp>600000</kp>
                <kd>3</kd>
              </ode>
            </contact>
            <friction>
              <ode>
                <mu>1e+07</mu>
                <mu2>1e+07</mu2>
                <fdir1>1 0 0</fdir1>
              </ode>
              <torsional>
                <ode/>
              </torsional>
            </friction>
            <bounce/>
          </surface>
          <max_contacts>10</max_contacts>
        </collision>
        <visual name='rear_caster_base_visual'>
          <pose>0 0 0 0 -0 0</pose>
          <geometry>
            <mesh>
              <scale>1 1 1</scale>
              <uri>/home/ikemura/ROS_workspaces/HKUST_RGD_SIM/src/onebot_description/meshes/caster_base2.dae</uri>
            </mesh>
          </geometry>
        </visual>
        <self_collide>0</self_collide>
        <enable_wind>0</enable_wind>
        <kinematic>0</kinematic>
      </link>
      <joint name='rear_cwheel' type='revolute'>
        <pose relative_to='rear_caster_base'>-0.02626 0 -0.042385 0 -0 0</pose>
        <parent>rear_caster_base</parent>
        <child>rear_caster_link</child>
        <axis>
          <xyz>0 1 0</xyz>
          <limit>
            <lower>-1e+16</lower>
            <upper>1e+16</upper>
          </limit>
          <dynamics>
            <spring_reference>0</spring_reference>
            <spring_stiffness>0</spring_stiffness>
          </dynamics>
        </axis>
      </joint>
      <link name='rear_caster_link'>
        <pose relative_to='rear_cwheel'>0 0 0 0 -0 0</pose>
        <inertial>
          <pose>0 0 0 0 -0 0</pose>
          <mass>0.03837</mass>
          <inertia>
            <ixx>8.221e-06</ixx>
            <ixy>0</ixy>
            <ixz>0</ixz>
            <iyy>1.3003e-05</iyy>
            <iyz>0</iyz>
            <izz>8.221e-06</izz>
          </inertia>
        </inertial>
        <collision name='rear_caster_link_collision'>
          <pose>0 0 0 1.57 -0 0</pose>
          <geometry>
            <cylinder>
              <length>0.011665</length>
              <radius>0.024165</radius>
            </cylinder>
          </geometry>
          <surface>
            <contact>
              <ode>
                <kp>600000</kp>
                <kd>3</kd>
              </ode>
            </contact>
            <friction>
              <ode>
                <mu>1e+07</mu>
                <mu2>1e+07</mu2>
                <fdir1>1 0 0</fdir1>
              </ode>
              <torsional>
                <ode/>
              </torsional>
            </friction>
            <bounce/>
          </surface>
          <max_contacts>10</max_contacts>
        </collision>
        <visual name='rear_caster_link_visual'>
          <pose>0 0 0 1.57 -0 0</pose>
          <geometry>
            <mesh>
              <scale>1 1 1</scale>
              <uri>/home/ikemura/ROS_workspaces/HKUST_RGD_SIM/src/onebot_description/meshes/caswheel.dae</uri>
            </mesh>
          </geometry>
        </visual>
        <velocity_decay>
          <linear>0.05</linear>
          <angular>0.05</angular>
        </velocity_decay>
        <self_collide>0</self_collide>
        <enable_wind>0</enable_wind>
        <kinematic>0</kinematic>
      </link>
      <joint name='right_wheel' type='revolute'>
        <pose relative_to='base_footprint'>-0.04 -0.14 0.04688 0 -0 0</pose>
        <parent>base_footprint</parent>
        <child>right_wheel_link</child>
        <axis>
          <xyz>0 1 0</xyz>
          <limit>
            <lower>-1e+16</lower>
            <upper>1e+16</upper>
          </limit>
          <dynamics>
            <damping>0.5</damping>
            <friction>100</friction>
            <spring_reference>0</spring_reference>
            <spring_stiffness>0</spring_stiffness>
          </dynamics>
        </axis>
      </joint>
      <link name='right_wheel_link'>
        <pose relative_to='right_wheel'>0 0 0 0 -0 0</pose>
        <inertial>
          <pose>0 0 0 0 -0 0</pose>
          <mass>0.144</mass>
          <inertia>
            <ixx>8.92986e-05</ixx>
            <ixy>0</ixy>
            <ixz>0</ixz>
            <iyy>0.000168983</iyy>
            <iyz>0</iyz>
            <izz>8.92986e-05</izz>
          </inertia>
        </inertial>
        <collision name='right_wheel_link_collision'>
          <pose>0 0 0 1.57 -0 0</pose>
          <geometry>
            <cylinder>
              <length>0.02</length>
              <radius>0.04688</radius>
            </cylinder>
          </geometry>
          <surface>
            <contact>
              <ode>
                <kp>600000</kp>
                <kd>3</kd>
              </ode>
            </contact>
            <friction>
              <ode>
                <mu>1e+07</mu>
                <mu2>1e+07</mu2>
                <fdir1>1 0 0</fdir1>
              </ode>
              <torsional>
                <ode/>
              </torsional>
            </friction>
            <bounce/>
          </surface>
          <max_contacts>10</max_contacts>
        </collision>
        <visual name='right_wheel_link_visual'>
          <pose>0 0 0 0 -0 1.57</pose>
          <geometry>
            <mesh>
              <scale>1 1 1</scale>
              <uri>/home/ikemura/ROS_workspaces/HKUST_RGD_SIM/src/onebot_description/meshes/wheel.dae</uri>
            </mesh>
          </geometry>
        </visual>
        <velocity_decay>
          <linear>0.05</linear>
          <angular>0.05</angular>
        </velocity_decay>
        <self_collide>0</self_collide>
        <enable_wind>0</enable_wind>
        <kinematic>0</kinematic>
      </link>
      <plugin name='imu_plugin' filename='libgazebo_ros_imu.so'>
        <alwaysOn>1</alwaysOn>
        <bodyName>base_footprint</bodyName>
        <topicName>imu</topicName>
        <serviceName>imu_service</serviceName>
        <gaussianNoise>0.0</gaussianNoise>
        <updateRate>20.0</updateRate>
        <robotNamespace>/</robotNamespace>
      </plugin>
      <plugin name='gazebo_ros_control' filename='libgazebo_ros_control.so'>
        <robotNamespace>/</robotNamespace>
        <legacyModeNS>1</legacyModeNS>
      </plugin>
      <frame name='camera_left_joint' attached_to='base_link'>
        <pose>0.12 -0.2 0.035 0 0 -1.75</pose>
      </frame>
      <frame name='camera_left_link' attached_to='camera_left_joint'/>
      <frame name='camera_right_joint' attached_to='base_link'>
        <pose>0.12 0.2 0.035 0 -0 1.75</pose>
      </frame>
      <frame name='camera_right_link' attached_to='camera_right_joint'/>
      <frame name='imu_joint' attached_to='base_link'>
        <pose>0 0 0.05 0 -0 0</pose>
      </frame>
      <frame name='imu_link' attached_to='imu_joint'/>
      <frame name='stereo_camera_joint' attached_to='base_link'>
        <pose>0.1 0 0.035 0 -0 0</pose>
      </frame>
      <frame name='stereo_camera_link' attached_to='stereo_camera_joint'/>
      <frame name='base_joint' attached_to='base_footprint'>
        <pose>0 0 0.09188 0 -0 0</pose>
      </frame>
      <frame name='base_link' attached_to='base_joint'/>
      <pose>0 0 0 0 -0 0</pose>
    </model>
  </world>
</sdf>
